Workbook

Sheet Summary
A1: ROLLS-ROYCE HOLDINGS PLC (LSE: RR.)
A2: Discounted Cash Flow Valuation | Base year FY2025A | Explicit forecast 2026E-2035E | Model date 11-Jul-2026
A3: FTSE 100 aerospace & defence: Civil Aerospace (52% of revenue), Defence (24%), Power Systems (24%). All figures £m unless stated.
A5: VALUATION SNAPSHOT
A6: Current share price (10-Jul-2026) | B6: =Assumptions!B6 -> 1438.4 | D6: Market capitalisation (£m) | E6: =Assumptions!B8 -> 119099.52
A7: DCF implied value per share | B7: =DCF!C61 -> 827.64806 | D7: Enterprise value — DCF (£m) | E7: =DCF!C53 -> 67115.759
A8: Implied upside / (downside) | B8: =DCF!C63 -> -0.42460507 | D8: PV of terminal value as % of EV | E8: =DCF!C54 -> 0.53126337
A9: WACC | B9: =WACC!B22 -> 0.095247314 | D9: Terminal growth rate | E9: =Assumptions!B15 -> 0.0225
A10: Market-implied perpetual growth (reverse DCF) | B10: =DCF!C75 -> 0.063945666 | D10: Market cap / FCFF 2026E | E10: =DCF!C69 -> 32.357229
A12: THE ONE-PARAGRAPH VIEW
A13: Rolls-Royce's transformation is real: FY2025 delivered £3.5bn underlying EBIT (17.3% margin), £3.3bn free cash flow and a £1.9bn net cash position, and management upgraded 2028 targets to £4.9-5.2bn EBIT and £5.0-5.3bn FCF. This model deliberately takes management's 2026 guidance and 2028 targets at face value, then fades growth toward GDP by 2035. Even on those generous operating assumptions, a 9.5% WACC base case values the shares well below the current price: the reverse DCF shows the market is paying for ~6% PERPETUAL growth — i.e. pricing in substantial value from options NOT in the base case (SMR leadership, narrowbody re-entry via UltraFan, a European defence supercycle) and/or a sub-8% discount rate. The interesting question for an investor is therefore not 'is RR a good business?' (it demonstrably is) but 'how much am I paying today for cash flows that do not yet exist?'
A15: BULL CASE DRIVERS (upside to base)
A16: • SMR: sole UK provider (3 units at Wylfa), CEZ commitment for up to 6 Czech units; profitable & FCF-positive by 2030 — carried at ~zero in this DCF.
A17: • Narrowbody re-entry via UltraFan partnership would roughly double the addressable civil market.
A18: • £7-9bn buyback (2026-28) shrinks the share count ~6-8% vs the static count used here; time-on-wing programme (+100% durability) structurally lifts LTSA margins.
A20: BEAR CASE / KEY RISKS
A21: • Valuation itself: at ~32x 2026E FCFF, execution must be flawless; any guidance miss compresses the multiple and the price simultaneously.
A22: • Concentration: Civil Aerospace aftermarket (widebody flying hours) drives the cash engine — a travel shock or Trent durability setback hits FCF directly.
A23: • Supply chain & tariffs remain a £150-200m annual cash drag per guidance; LTSA accounting means margin quality relies on long-dated contract estimates.
A25: MODEL GUIDE & COLOUR LEGEND
A26: Blue font | B26: Hardcoded input / analyst assumption — edit these
A27: Black font | B27: Formula — do not overwrite
A28: Green font | B28: Link to another sheet
A29: Yellow fill | B29: Key value drivers and headline outputs
A30: Tabs | B30: Summary → Assumptions → WACC → DCF → Sensitivity
A32: Prepared from the RR FY2025 results announcement (26-Feb-2026) and market data as of 10-Jul-2026. Educational analysis, not investment advice.

Sheet Assumptions
A1: ROLLS-ROYCE HOLDINGS PLC — GLOBAL VALUATION ASSUMPTIONS
A2: All figures £m unless stated. Blue = hardcoded input (editable). Yellow = key value drivers.
A4: MARKET & CAPITALISATION DATA
A5: Valuation date | B5: 30-Jun-2026 | D5: Mid-year 2026 valuation date; FY2026 cash flow is 50%-weighted for the remaining half year.
A6: Current share price (pence) | B6: 1438.4 | D6: LSE: RR. close 10-Jul-2026 (Investing.com). Update before use.
A7: Shares outstanding (m) | B7: 8280 | D7: c.8.28bn ordinary shares in issue (LSE.co.uk, Jul-2026), net of 2025 £1bn + Jan/Feb-2026 £200m buyback cancellations.
A8: Market capitalisation (£m) | B8: =B6*B7/100 -> 119099.52 | D8: Calculated: price x shares / 100.
A9: Net cash / (debt), incl. lease liabilities (£m) | B9: 1895 | D9: FY2025 press release, balance sheet: net cash £1,895m at 31-Dec-2025 (gross debt £2.8bn, leases £1.5bn, cash £6.2bn).
A10: Net post-retirement deficit (£m) | B10: 606 | D10: FY2025 balance sheet: deficits £892m less surpluses £286m. UK scheme buy-out expected 2026.
A11: Non-controlling interests (£m) | B11: 27 | D11: Book value of NCI, 31-Dec-2025 balance sheet.
A13: TAX, TERMINAL & TIMING ASSUMPTIONS
A14: Marginal tax rate (terminal) | B14: 0.25 | D14: UK statutory corporation tax rate of 25%. Conservative vs FY2025 underlying effective rate of c.17.7%, which was flattered by deferred tax credits.
A15: Terminal growth rate (g) | B15: 0.0225 | D15: Long-run nominal growth c. in line with UK/global GDP+inflation mix; below long-term aviation RPK growth (~3-4%) for conservatism.
A16: FY2026 cash flow weighting | B16: 0.5 | D16: Half of FY2026 FCFF remains uncollected at the 30-Jun-2026 valuation date.
A17: Discounting convention | B17: Mid-year | D17: Cash flows arrive evenly through each year, so each year is discounted from its mid-point. Terminal value discounted from 31-Dec-2035 (t = 9.5).
A19: FY2025 REPORTED ANCHORS (for reference / tie-out)
A20: Underlying revenue FY2025 | B20: 20059 | D20: Civil £10,382m / Defence £4,772m / Power Systems £4,892m / Other £13m
A21: Underlying operating profit FY2025 | B21: 3462 | D21: 17.3% margin. Civil 20.5% / Defence 14.4% / Power Systems 17.4%
A22: Free cash flow FY2025 (company definition) | B22: 3270 | D22: Post-tax, post-interest, incl. LTSA balance growth of £501m and working-capital inflow of £421m
A23: Depreciation, amortisation & impairment FY2025 | B23: 900 | D23: Underlying funds-flow basis (4.5% of revenue)
A24: Capital expenditure FY2025 | B24: 978 | D24: PP&E £621m + intangible additions £364m, gross of disposals (4.9% of revenue)
A26: COMPANY GUIDANCE THE FORECAST IS CALIBRATED TO
A27: 2026 guidance — underlying operating profit | B27: £4.0bn – £4.2bn | D27: Model FY2026E EBIT sits at the low end of guidance (deliberately conservative).
A28: 2026 guidance — free cash flow | B28: £3.6bn – £3.8bn | D28: Model FY2026E FCFF of ~£3.6-3.7bn is consistent (definitions differ slightly: FCFF is pre-net-interest).
A29: 2028 mid-term target — operating profit / margin | B29: £4.9bn – £5.2bn / 18%–20% | D29: Model FY2028E EBIT ≈ £5.1bn at a 19.0% margin — inside the target band.
A30: 2028 mid-term target — free cash flow | B30: £5.0bn – £5.3bn | D30: Company FCF target includes £0.8-1.2bn p.a. LTSA balance growth; model assumes a fading, more conservative inflow.
A31: Capital returns | B31: £7bn-£9bn buyback 2026-28; 9.5p FY25 dividend | D31: Distributions do not change enterprise value but will shrink the share count vs the (static) 8.28bn used here — upside to per-share value.
A33: SOURCES
A34: • Rolls-Royce Holdings plc 2025 Full Year Results press release, 26-Feb-2026 (rolls-royce.com/investors) — all FY2024A/FY2025A financials, 2026 guidance, 2028 mid-term targets, balance sheet.
A35: • LSE.co.uk / Investing.com, 10-Jul-2026 — share price and shares in issue.
A36: • UK 10-year gilt yield (c.4.5%, mid-2026) — risk-free rate. Update to live yield before use.
A37: • All forecast drivers (growth, margins, capex, working capital, WACC inputs) are analyst assumptions — set out cell-by-cell in blue on the DCF and WACC tabs.

Sheet WACC
A1: WEIGHTED AVERAGE COST OF CAPITAL
A3: COST OF EQUITY (CAPM)
A4: Risk-free rate (UK 10-year gilt) | B4: 0.045 | D4: Approximate UK 10Y gilt yield, mid-2026. GBP cash flows discounted at a GBP rate.
A5: Equity risk premium | B5: 0.0475 | D5: Mature-market ERP (Damodaran-style 4.5-5.0% range).
A6: Levered beta | B6: 1.1 | D6: Judgement: raw 5Y beta (~1.4) is distorted by COVID-era distress; 2Y beta and post-transformation cash-flow stability point lower. Flexed in sensitivities.
A7: Cost of equity (Ke) | B7: =B4+B6*B5 -> 0.09725
A9: COST OF DEBT
A10: Pre-tax cost of debt (Kd) | B10: 0.0525 | D10: Blended bond coupon / gilt + ~75-100bps spread; investment-grade issuer with net cash.
A11: Marginal tax rate | B11: =Assumptions!B14 -> 0.25
A12: After-tax cost of debt | B12: =B10*(1-B11) -> 0.039375
A14: CAPITAL STRUCTURE (MARKET VALUES)
A15: Market value of equity (£m) | B15: =Assumptions!B8 -> 119099.52
A16: Gross debt incl. lease liabilities (£m) | B16: 4269 | D16: 31-Dec-2025: borrowings £2,799m + lease liabilities £1,470m. RR holds NET CASH; gross debt used only for weighting.
A17: Total capitalisation (£m) | B17: =B15+B16 -> 123368.52
A18: Weight of equity | B18: =B15/B17 -> 0.96539636
A19: Weight of debt | B19: =B16/B17 -> 0.034603641
A21: WACC
A22: WACC | B22: =B7*B18+B12*B19 -> 0.095247314 | D22: With ~96% equity weighting, WACC ≈ cost of equity. Sensitivity tab flexes 7.5%-11.0%.

Sheet DCF
A1: DISCOUNTED CASH FLOW — ROLLS-ROYCE HOLDINGS PLC (£m unless stated)
A3: Fiscal year ending 31 December | C3: 2024A | D3: 2025A | E3: 2026E | F3: 2027E | G3: 2028E | H3: 2029E | I3: 2030E | J3: 2031E | K3: 2032E | L3: 2033E | M3: 2034E | N3: 2035E
A4: SEGMENT REVENUE BUILD
A5: Civil Aerospace | C5: 9040 | D5: 10382 | E5: =D5*(1+E6) -> 11524.02 | F5: =E5*(1+F6) -> 12676.422 | G5: =F5*(1+G6) -> 13817.3 | H5: =G5*(1+H6) -> 14922.684 | I5: =H5*(1+I6) -> 15967.272 | J5: =I5*(1+J6) -> 17005.145 | K5: =J5*(1+K6) -> 18025.453 | L5: =K5*(1+L6) -> 19016.853 | ... N5: =M5*(1+N6) -> 20866.242
A6: growth % | D6: =D5/C5-1 -> 0.14845133 | E6: 0.11 | F6: 0.1 | G6: 0.09 | H6: 0.08 | I6: 0.07 | J6: 0.065 | K6: 0.06 | L6: 0.055 | M6: 0.05 | N6: 0.045
A7: Defence | C7: 4522 | D7: 4772 | E7: =D7*(1+E8) -> 5153.76 | F7: =E7*(1+F8) -> 5566.0608 | G7: =F7*(1+G8) -> 6011.3457 | H7: =G7*(1+H8) -> 6492.2533 | I7: =H7*(1+I8) -> 6979.1723 | J7: =I7*(1+J8) -> 7467.7144 | K7: =J7*(1+K8) -> 7953.1158 | L7: =K7*(1+L8) -> 8430.3028 | ... N7: =M7*(1+N8) -> 9338.6679
A8: growth % | D8: =D7/C7-1 -> 0.055285272 | E8: 0.08 | F8: 0.08 | G8: 0.08 | H8: 0.08 | I8: 0.075 | J8: 0.07 | K8: 0.065 | L8: 0.06 | M8: 0.055 | N8: 0.05
A9: Power Systems | C9: 4271 | D9: 4892 | E9: =D9*(1+E10) -> 5576.88 | F9: =E9*(1+F10) -> 6246.1056 | G9: =F9*(1+G10) -> 6995.6383 | H9: =G9*(1+H10) -> 7695.2021 | I9: =H9*(1+I10) -> 8387.7703 | J9: =I9*(1+J10) -> 9058.7919 | K9: =J9*(1+K10) -> 9692.9073 | L9: =K9*(1+L10) -> 10322.946 | ... N9: =M9*(1+N10) -> 11544.151
A10: growth % | D10: =D9/C9-1 -> 0.1453992 | E10: 0.14 | F10: 0.12 | G10: 0.12 | H10: 0.1 | I10: 0.09 | J10: 0.08 | K10: 0.07 | L10: 0.065 | M10: 0.06 | N10: 0.055
A11: All Other Businesses | C11: 15 | D11: 13 | E11: =$D$11 -> 13 | F11: =$D$11 -> 13 | G11: =$D$11 -> 13 | H11: =$D$11 -> 13 | I11: =$D$11 -> 13 | J11: =$D$11 -> 13 | K11: =$D$11 -> 13 | L11: =$D$11 -> 13 | ... N11: =$D$11 -> 13
A12: Total underlying revenue | C12: =SUM(C5,C7,C9,C11) -> 17848 | D12: =SUM(D5,D7,D9,D11) -> 20059 | E12: =SUM(E5,E7,E9,E11) -> 22267.66 | F12: =SUM(F5,F7,F9,F11) -> 24501.588 | G12: =SUM(G5,G7,G9,G11) -> 26837.284 | H12: =SUM(H5,H7,H9,H11) -> 29123.139 | I12: =SUM(I5,I7,I9,I11) -> 31347.214 | J12: =SUM(J5,J7,J9,J11) -> 33544.651 | ... N12: =SUM(N5,N7,N9,N11) -> 41762.061
A13: growth % | D13: =D12/C12-1 -> 0.12387943 | E13: =E12/D12-1 -> 0.11010818 | F13: =F12/E12-1 -> 0.10032165 | G13: =G12/F12-1 -> 0.09532833 | H13: =H12/G12-1 -> 0.085174621 | I13: =I12/H12-1 -> 0.076367971 | J13: =J12/I12-1 -> 0.070099892 | K13: =K12/J12-1 -> 0.063790366 | ... N13: =N12/M12-1 -> 0.048850318
A15: UNDERLYING OPERATING PROFIT (EBIT)
A16: Civil Aerospace EBIT | C16: 1505 | D16: 2130 | E16: =E5*E17 -> 2454.6163 | F16: =F5*F17 -> 2738.1072 | G16: =G5*G17 -> 3039.806 | H16: =H5*H17 -> 3297.9132 | I16: =I5*I17 -> 3544.7344 | J16: =J5*J17 -> 3792.1472 | K16: =K5*K17 -> 4037.7015 | L16: =L5*L17 -> 4278.792 | ... N16: =N5*N17 -> 4694.9045
A17: margin % | C17: =C16/C5 -> 0.1664823 | D17: =D16/D5 -> 0.20516278 | E17: 0.213 | F17: 0.216 | G17: 0.22 | H17: 0.221 | I17: 0.222 | J17: 0.223 | K17: 0.224 | L17: 0.225 | M17: 0.225 | N17: 0.225
A18: Defence EBIT | C18: 644 | D18: 689 | E18: =E7*E19 -> 752.44896 | F18: =F7*F19 -> 823.777 | G18: =G7*G19 -> 901.70185 | H18: =H7*H19 -> 973.838 | I18: =I7*I19 -> 1046.8758 | J18: =J7*J19 -> 1120.1572 | K18: =K7*K19 -> 1192.9674 | L18: =L7*L19 -> 1264.5454 | ... N18: =N7*N19 -> 1400.8002
A19: margin % | C19: =C18/C7 -> 0.14241486 | D19: =D18/D7 -> 0.14438391 | E19: 0.146 | F19: 0.148 | G19: 0.15 | H19: 0.15 | I19: 0.15 | J19: 0.15 | K19: 0.15 | L19: 0.15 | M19: 0.15 | N19: 0.15
A20: Power Systems EBIT | C20: 560 | D20: 852 | E20: =E9*E21 -> 1003.8384 | F20: =F9*F21 -> 1155.5295 | G20: =G9*G21 -> 1329.1713 | H20: =H9*H21 -> 1462.0884 | I20: =I9*I21 -> 1593.6764 | J20: =J9*J21 -> 1721.1705 | K20: =K9*K21 -> 1841.6524 | L20: =L9*L21 -> 1961.3598 | ... N20: =N9*N21 -> 2193.3887
A21: margin % | C21: =C20/C9 -> 0.13111683 | D21: =D20/D9 -> 0.1741619 | E21: 0.18 | F21: 0.185 | G21: 0.19 | H21: 0.19 | I21: 0.19 | J21: 0.19 | K21: 0.19 | L21: 0.19 | M21: 0.19 | N21: 0.19
A22: Corporate, SMR share & other | C22: -245 | D22: -209 | E22: -200 | F22: -180 | G22: -160 | H22: -150 | I22: -150 | J22: -150 | K22: -150 | L22: -150 | M22: -150 | N22: -150
A23: Group underlying EBIT | C23: =SUM(C16,C18,C20,C22) -> 2464 | D23: =SUM(D16,D18,D20,D22) -> 3462 | E23: =SUM(E16,E18,E20,E22) -> 4010.9036 | F23: =SUM(F16,F18,F20,F22) -> 4537.4137 | G23: =SUM(G16,G18,G20,G22) -> 5110.6791 | H23: =SUM(H16,H18,H20,H22) -> 5583.8396 | I23: =SUM(I16,I18,I20,I22) -> 6035.2866 | J23: =SUM(J16,J18,J20,J22) -> 6483.4748 | ... N23: =SUM(N16,N18,N20,N22) -> 8139.0933
A24: margin % | C24: =C23/C12 -> 0.13805468 | D24: =D23/D12 -> 0.17259086 | E24: =E23/E12 -> 0.18012237 | F24: =F23/F12 -> 0.18518855 | G24: =G23/G12 -> 0.19043205 | H24: =H23/H12 -> 0.19173206 | I24: =I23/I12 -> 0.19253023 | J24: =J23/J12 -> 0.19327895 | ... N24: =N23/N12 -> 0.19489204
A26: UNLEVERED FREE CASH FLOW (FCFF)
A27: Cash tax rate % | E27: 0.21 | F27: 0.22 | G27: 0.23 | H27: 0.24 | I27: 0.25 | J27: 0.25 | K27: 0.25 | L27: 0.25 | M27: 0.25 | N27: 0.25
A28: Cash taxes on EBIT | E28: =-E23*E27 -> -842.28976 | F28: =-F23*F27 -> -998.23101 | G28: =-G23*G27 -> -1175.4562 | H28: =-H23*H27 -> -1340.1215 | I28: =-I23*I27 -> -1508.8216 | J28: =-J23*J27 -> -1620.8687 | K28: =-K23*K27 -> -1730.5803 | L28: =-L23*L27 -> -1838.6743 | ... N28: =-N23*N27 -> -2034.7733
A29: NOPAT | E29: =E23+E28 -> 3168.6139 | F29: =F23+F28 -> 3539.1827 | G29: =G23+G28 -> 3935.2229 | H29: =H23+H28 -> 4243.7181 | I29: =I23+I28 -> 4526.4649 | J29: =J23+J28 -> 4862.6061 | K29: =K23+K28 -> 5191.741 | L29: =L23+L28 -> 5516.0229 | ... N29: =N23+N28 -> 6104.32
A30: D&A (% of revenue) | E30: 0.045 | F30: 0.045 | G30: 0.045 | H30: 0.044 | I30: 0.044 | J30: 0.044 | K30: 0.043 | L30: 0.043 | M30: 0.043 | N30: 0.043
A31: (+) Depreciation & amortisation | E31: =E12*E30 -> 1002.0447 | F31: =F12*F30 -> 1102.5715 | G31: =G12*G30 -> 1207.6778 | H31: =H12*H30 -> 1281.4181 | I31: =I12*I30 -> 1379.2774 | J31: =J12*J30 -> 1475.9646 | K31: =K12*K30 -> 1534.4325 | L31: =L12*L30 -> 1624.6734 | ... N31: =N12*N30 -> 1795.7686
A32: Capex (% of revenue) | E32: 0.052 | F32: 0.052 | G32: 0.052 | H32: 0.05 | I32: 0.049 | J32: 0.048 | K32: 0.047 | L32: 0.046 | M32: 0.045 | N32: 0.045
A33: (-) Capital expenditure | E33: =-E12*E32 -> -1157.9183 | F33: =-F12*F32 -> -1274.0826 | G33: =-G12*G32 -> -1395.5388 | H33: =-H12*H32 -> -1456.157 | I33: =-I12*I32 -> -1536.0135 | J33: =-J12*J32 -> -1610.1432 | K33: =-K12*K32 -> -1677.1704 | L33: =-L12*L32 -> -1738.0227 | ... N33: =-N12*N32 -> -1879.2927
A34: LTSA & working capital inflow (% of revenue) | E34: 0.03 | F34: 0.028 | G34: 0.026 | H34: 0.022 | I34: 0.018 | J34: 0.015 | K34: 0.012 | L34: 0.01 | M34: 0.008 | N34: 0.006
A35: (+) LTSA balance growth & working capital | E35: =E12*E34 -> 668.0298 | F35: =F12*F34 -> 686.04448 | G35: =G12*G34 -> 697.76938 | H35: =H12*H34 -> 640.70907 | I35: =I12*I34 -> 564.24986 | J35: =J12*J34 -> 503.16976 | K35: =K12*K34 -> 428.21372 | L35: =L12*L34 -> 377.83102 | ... N35: =N12*N34 -> 250.57237
A36: Unlevered free cash flow (FCFF) | E36: =E29+E31+E33+E35 -> 3680.77 | F36: =F29+F31+F33+F35 -> 4053.716 | G36: =G29+G31+G33+G35 -> 4445.1313 | H36: =H29+H31+H33+H35 -> 4709.6883 | I36: =I29+I31+I33+I35 -> 4933.9787 | J36: =J29+J31+J33+J35 -> 5231.5973 | K36: =K29+K31+K33+K35 -> 5477.2168 | L36: =L29+L31+L33+L35 -> 5780.5046 | ... N36: =N29+N31+N33+N35 -> 6271.3682
A37: Memo: company-defined free cash flow | C37: 2425 | D37: 3270 | E37: guide £3.6-3.8bn
A39: DISCOUNTING (mid-year convention; valuation date 30-Jun-2026)
A40: Recognition weight (share of year remaining) | E40: =Assumptions!B16 -> 0.5 | F40: 1 | G40: 1 | H40: 1 | I40: 1 | J40: 1 | K40: 1 | L40: 1 | M40: 1 | N40: 1
A41: Discount period (years, mid-year) | E41: =0.5*E40 -> 0.25 | F41: 1 | G41: =F41+1 -> 2 | H41: =G41+1 -> 3 | I41: =H41+1 -> 4 | J41: =I41+1 -> 5 | K41: =J41+1 -> 6 | L41: =K41+1 -> 7 | M41: =L41+1 -> 8 | N41: =M41+1 -> 9
A42: Discountable cash flow | E42: =E36*E40 -> 1840.385 | F42: =F36*F40 -> 4053.716 | G42: =G36*G40 -> 4445.1313 | H42: =H36*H40 -> 4709.6883 | I42: =I36*I40 -> 4933.9787 | J42: =J36*J40 -> 5231.5973 | K42: =K36*K40 -> 5477.2168 | L42: =L36*L40 -> 5780.5046 | ... N42: =N36*N40 -> 6271.3682
A43: Discount factor | E43: =1/(1+WACC!$B$22)^E41 -> 0.97751167 | F43: =1/(1+WACC!$B$22)^F41 -> 0.91303579 | G43: =1/(1+WACC!$B$22)^G41 -> 0.83363436 | H43: =1/(1+WACC!$B$22)^H41 -> 0.76113801 | I43: =1/(1+WACC!$B$22)^I41 -> 0.69494624 | J43: =1/(1+WACC!$B$22)^J41 -> 0.6345108 | K43: =1/(1+WACC!$B$22)^K41 -> 0.57933107 | L43: =1/(1+WACC!$B$22)^L41 -> 0.52895 | ... N43: =1/(1+WACC!$B$22)^N41 -> 0.44095089
A44: PV of FCFF | E44: =E42*E43 -> 1798.9978 | F44: =F42*F43 -> 3701.1878 | G44: =G42*G43 -> 3705.6142 | H44: =H42*H43 -> 3584.7228 | I44: =I42*I43 -> 3428.85 | J44: =J42*J43 -> 3319.505 | K44: =K42*K43 -> 3173.1218 | L44: =L42*L43 -> 3057.5979 | ... N44: =N42*N43 -> 2765.3654
...

Sheet Sensitivity
A1: SENSITIVITY ANALYSIS — IMPLIED VALUE PER SHARE (pence)
A2: Fully live: every cell re-runs the discounting engine against the DCF cash flows. Base case: WACC per WACC tab, g per Assumptions.
A4: 1) WACC x TERMINAL GROWTH
A5: WACC \ g | B5: 0.0125 | C5: 0.0175 | D5: 0.0225 | E5: 0.0275 | F5: 0.0325
A6: 0.075 | B6: =(SUMPRODUCT(DCF!$E$42:$N$42,(1+$A6)^(-DCF!$E$41:$N$41))+DCF!$C$48*(1+B$5)/($A6-B$5)/(1+$A6)^DCF!$C$51+DCF!$C$58)/DCF!$C$60*100 -> 1023.3672 | C6: =(SUMPRODUCT(DCF!$E$42:$N$42,(1+$A6)^(-DCF!$E$41:$N$41))+DCF!$C$48*(1+C$5)/($A6-C$5)/(1+$A6)^DCF!$C$51+DCF!$C$58)/DCF!$C$60*100 -> 1078.0781 | D6: =(SUMPRODUCT(DCF!$E$42:$N$42,(1+$A6)^(-DCF!$E$41:$N$41))+DCF!$C$48*(1+D$5)/($A6-D$5)/(1+$A6)^DCF!$C$51+DCF!$C$58)/DCF!$C$60*100 -> 1143.2101 | E6: =(SUMPRODUCT(DCF!$E$42:$N$42,(1+$A6)^(-DCF!$E$41:$N$41))+DCF!$C$48*(1+E$5)/($A6-E$5)/(1+$A6)^DCF!$C$51+DCF!$C$58)/DCF!$C$60*100 -> 1222.0541 | F6: =(SUMPRODUCT(DCF!$E$42:$N$42,(1+$A6)^(-DCF!$E$41:$N$41))+DCF!$C$48*(1+F$5)/($A6-F$5)/(1+$A6)^DCF!$C$51+DCF!$C$58)/DCF!$C$60*100 -> 1319.4496
A7: 0.08 | B7: =(SUMPRODUCT(DCF!$E$42:$N$42,(1+$A7)^(-DCF!$E$41:$N$41))+DCF!$C$48*(1+B$5)/($A7-B$5)/(1+$A7)^DCF!$C$51+DCF!$C$58)/DCF!$C$60*100 -> 947.04757 | C7: =(SUMPRODUCT(DCF!$E$42:$N$42,(1+$A7)^(-DCF!$E$41:$N$41))+DCF!$C$48*(1+C$5)/($A7-C$5)/(1+$A7)^DCF!$C$51+DCF!$C$58)/DCF!$C$60*100 -> 991.85065 | D7: =(SUMPRODUCT(DCF!$E$42:$N$42,(1+$A7)^(-DCF!$E$41:$N$41))+DCF!$C$48*(1+D$5)/($A7-D$5)/(1+$A7)^DCF!$C$51+DCF!$C$58)/DCF!$C$60*100 -> 1044.4456 | E7: =(SUMPRODUCT(DCF!$E$42:$N$42,(1+$A7)^(-DCF!$E$41:$N$41))+DCF!$C$48*(1+E$5)/($A7-E$5)/(1+$A7)^DCF!$C$51+DCF!$C$58)/DCF!$C$60*100 -> 1107.0586 | F7: =(SUMPRODUCT(DCF!$E$42:$N$42,(1+$A7)^(-DCF!$E$41:$N$41))+DCF!$C$48*(1+F$5)/($A7-F$5)/(1+$A7)^DCF!$C$51+DCF!$C$58)/DCF!$C$60*100 -> 1182.8533
A8: 0.085 | B8: =(SUMPRODUCT(DCF!$E$42:$N$42,(1+$A8)^(-DCF!$E$41:$N$41))+DCF!$C$48*(1+B$5)/($A8-B$5)/(1+$A8)^DCF!$C$51+DCF!$C$58)/DCF!$C$60*100 -> 881.37842 | C8: =(SUMPRODUCT(DCF!$E$42:$N$42,(1+$A8)^(-DCF!$E$41:$N$41))+DCF!$C$48*(1+C$5)/($A8-C$5)/(1+$A8)^DCF!$C$51+DCF!$C$58)/DCF!$C$60*100 -> 918.51475 | D8: =(SUMPRODUCT(DCF!$E$42:$N$42,(1+$A8)^(-DCF!$E$41:$N$41))+DCF!$C$48*(1+D$5)/($A8-D$5)/(1+$A8)^DCF!$C$51+DCF!$C$58)/DCF!$C$60*100 -> 961.5929 | E8: =(SUMPRODUCT(DCF!$E$42:$N$42,(1+$A8)^(-DCF!$E$41:$N$41))+DCF!$C$48*(1+E$5)/($A8-E$5)/(1+$A8)^DCF!$C$51+DCF!$C$58)/DCF!$C$60*100 -> 1012.1629 | F8: =(SUMPRODUCT(DCF!$E$42:$N$42,(1+$A8)^(-DCF!$E$41:$N$41))+DCF!$C$48*(1+F$5)/($A8-F$5)/(1+$A8)^DCF!$C$51+DCF!$C$58)/DCF!$C$60*100 -> 1072.3653
A9: 0.09 | B9: =(SUMPRODUCT(DCF!$E$42:$N$42,(1+$A9)^(-DCF!$E$41:$N$41))+DCF!$C$48*(1+B$5)/($A9-B$5)/(1+$A9)^DCF!$C$51+DCF!$C$58)/DCF!$C$60*100 -> 824.2917 | C9: =(SUMPRODUCT(DCF!$E$42:$N$42,(1+$A9)^(-DCF!$E$41:$N$41))+DCF!$C$48*(1+C$5)/($A9-C$5)/(1+$A9)^DCF!$C$51+DCF!$C$58)/DCF!$C$60*100 -> 855.39658 | D9: =(SUMPRODUCT(DCF!$E$42:$N$42,(1+$A9)^(-DCF!$E$41:$N$41))+DCF!$C$48*(1+D$5)/($A9-D$5)/(1+$A9)^DCF!$C$51+DCF!$C$58)/DCF!$C$60*100 -> 891.1096 | E9: =(SUMPRODUCT(DCF!$E$42:$N$42,(1+$A9)^(-DCF!$E$41:$N$41))+DCF!$C$48*(1+E$5)/($A9-E$5)/(1+$A9)^DCF!$C$51+DCF!$C$58)/DCF!$C$60*100 -> 932.5367 | F9: =(SUMPRODUCT(DCF!$E$42:$N$42,(1+$A9)^(-DCF!$E$41:$N$41))+DCF!$C$48*(1+F$5)/($A9-F$5)/(1+$A9)^DCF!$C$51+DCF!$C$58)/DCF!$C$60*100 -> 981.16852
A10: 0.095 | B10: =(SUMPRODUCT(DCF!$E$42:$N$42,(1+$A10)^(-DCF!$E$41:$N$41))+DCF!$C$48*(1+B$5)/($A10-B$5)/(1+$A10)^DCF!$C$51+DCF!$C$58)/DCF!$C$60*100 -> 774.22113 | C10: =(SUMPRODUCT(DCF!$E$42:$N$42,(1+$A10)^(-DCF!$E$41:$N$41))+DCF!$C$48*(1+C$5)/($A10-C$5)/(1+$A10)^DCF!$C$51+DCF!$C$58)/DCF!$C$60*100 -> 800.51278 | D10: =(SUMPRODUCT(DCF!$E$42:$N$42,(1+$A10)^(-DCF!$E$41:$N$41))+DCF!$C$48*(1+D$5)/($A10-D$5)/(1+$A10)^DCF!$C$51+DCF!$C$58)/DCF!$C$60*100 -> 830.43087 | E10: =(SUMPRODUCT(DCF!$E$42:$N$42,(1+$A10)^(-DCF!$E$41:$N$41))+DCF!$C$48*(1+E$5)/($A10-E$5)/(1+$A10)^DCF!$C$51+DCF!$C$58)/DCF!$C$60*100 -> 864.78127 | F10: =(SUMPRODUCT(DCF!$E$42:$N$42,(1+$A10)^(-DCF!$E$41:$N$41))+DCF!$C$48*(1+F$5)/($A10-F$5)/(1+$A10)^DCF!$C$51+DCF!$C$58)/DCF!$C$60*100 -> 904.62773
A11: 0.1 | B11: =(SUMPRODUCT(DCF!$E$42:$N$42,(1+$A11)^(-DCF!$E$41:$N$41))+DCF!$C$48*(1+B$5)/($A11-B$5)/(1+$A11)^DCF!$C$51+DCF!$C$58)/DCF!$C$60*100 -> 729.95878 | C11: =(SUMPRODUCT(DCF!$E$42:$N$42,(1+$A11)^(-DCF!$E$41:$N$41))+DCF!$C$48*(1+C$5)/($A11-C$5)/(1+$A11)^DCF!$C$51+DCF!$C$58)/DCF!$C$60*100 -> 752.36114 | D11: =(SUMPRODUCT(DCF!$E$42:$N$42,(1+$A11)^(-DCF!$E$41:$N$41))+DCF!$C$48*(1+D$5)/($A11-D$5)/(1+$A11)^DCF!$C$51+DCF!$C$58)/DCF!$C$60*100 -> 777.65412 | E11: =(SUMPRODUCT(DCF!$E$42:$N$42,(1+$A11)^(-DCF!$E$41:$N$41))+DCF!$C$48*(1+E$5)/($A11-E$5)/(1+$A11)^DCF!$C$51+DCF!$C$58)/DCF!$C$60*100 -> 806.4358 | F11: =(SUMPRODUCT(DCF!$E$42:$N$42,(1+$A11)^(-DCF!$E$41:$N$41))+DCF!$C$48*(1+F$5)/($A11-F$5)/(1+$A11)^DCF!$C$51+DCF!$C$58)/DCF!$C$60*100 -> 839.48142
A12: 0.105 | B12: =(SUMPRODUCT(DCF!$E$42:$N$42,(1+$A12)^(-DCF!$E$41:$N$41))+DCF!$C$48*(1+B$5)/($A12-B$5)/(1+$A12)^DCF!$C$51+DCF!$C$58)/DCF!$C$60*100 -> 690.55822 | C12: =(SUMPRODUCT(DCF!$E$42:$N$42,(1+$A12)^(-DCF!$E$41:$N$41))+DCF!$C$48*(1+C$5)/($A12-C$5)/(1+$A12)^DCF!$C$51+DCF!$C$58)/DCF!$C$60*100 -> 709.78313 | D12: =(SUMPRODUCT(DCF!$E$42:$N$42,(1+$A12)^(-DCF!$E$41:$N$41))+DCF!$C$48*(1+D$5)/($A12-D$5)/(1+$A12)^DCF!$C$51+DCF!$C$58)/DCF!$C$60*100 -> 731.33834 | E12: =(SUMPRODUCT(DCF!$E$42:$N$42,(1+$A12)^(-DCF!$E$41:$N$41))+DCF!$C$48*(1+E$5)/($A12-E$5)/(1+$A12)^DCF!$C$51+DCF!$C$58)/DCF!$C$60*100 -> 755.67486 | F12: =(SUMPRODUCT(DCF!$E$42:$N$42,(1+$A12)^(-DCF!$E$41:$N$41))+DCF!$C$48*(1+F$5)/($A12-F$5)/(1+$A12)^DCF!$C$51+DCF!$C$58)/DCF!$C$60*100 -> 783.36815
A13: 0.11 | B13: =(SUMPRODUCT(DCF!$E$42:$N$42,(1+$A13)^(-DCF!$E$41:$N$41))+DCF!$C$48*(1+B$5)/($A13-B$5)/(1+$A13)^DCF!$C$51+DCF!$C$58)/DCF!$C$60*100 -> 655.26741 | C13: =(SUMPRODUCT(DCF!$E$42:$N$42,(1+$A13)^(-DCF!$E$41:$N$41))+DCF!$C$48*(1+C$5)/($A13-C$5)/(1+$A13)^DCF!$C$51+DCF!$C$58)/DCF!$C$60*100 -> 671.87099 | D13: =(SUMPRODUCT(DCF!$E$42:$N$42,(1+$A13)^(-DCF!$E$41:$N$41))+DCF!$C$48*(1+D$5)/($A13-D$5)/(1+$A13)^DCF!$C$51+DCF!$C$58)/DCF!$C$60*100 -> 690.37213 | E13: =(SUMPRODUCT(DCF!$E$42:$N$42,(1+$A13)^(-DCF!$E$41:$N$41))+DCF!$C$48*(1+E$5)/($A13-E$5)/(1+$A13)^DCF!$C$51+DCF!$C$58)/DCF!$C$60*100 -> 711.11584 | F13: =(SUMPRODUCT(DCF!$E$42:$N$42,(1+$A13)^(-DCF!$E$41:$N$41))+DCF!$C$48*(1+F$5)/($A13-F$5)/(1+$A13)^DCF!$C$51+DCF!$C$58)/DCF!$C$60*100 -> 734.53614
A16: 2) TERMINAL EBIT MARGIN x TERMINAL GROWTH (at base WACC)
A17: Margin \ g | B17: 0.0125 | C17: 0.0175 | D17: 0.0225 | E17: 0.0275 | F17: 0.0325
A18: 0.17 | B18: =(DCF!$C$47+(DCF!$N$12*$A18*(1-DCF!$N$27)+DCF!$N$31+DCF!$N$33)*(1+B$17)/(WACC!$B$22-B$17)/(1+WACC!$B$22)^DCF!$C$51+DCF!$C$58)/DCF!$C$60*100 -> 723.35848 | C18: =(DCF!$C$47+(DCF!$N$12*$A18*(1-DCF!$N$27)+DCF!$N$31+DCF!$N$33)*(1+C$17)/(WACC!$B$22-C$17)/(1+WACC!$B$22)^DCF!$C$51+DCF!$C$58)/DCF!$C$60*100 -> 746.06091 | D18: =(DCF!$C$47+(DCF!$N$12*$A18*(1-DCF!$N$27)+DCF!$N$31+DCF!$N$33)*(1+D$17)/(WACC!$B$22-D$17)/(1+WACC!$B$22)^DCF!$C$51+DCF!$C$58)/DCF!$C$60*100 -> 771.88407 | E18: =(DCF!$C$47+(DCF!$N$12*$A18*(1-DCF!$N$27)+DCF!$N$31+DCF!$N$33)*(1+E$17)/(WACC!$B$22-E$17)/(1+WACC!$B$22)^DCF!$C$51+DCF!$C$58)/DCF!$C$60*100 -> 801.51891 | F18: =(DCF!$C$47+(DCF!$N$12*$A18*(1-DCF!$N$27)+DCF!$N$31+DCF!$N$33)*(1+F$17)/(WACC!$B$22-F$17)/(1+WACC!$B$22)^DCF!$C$51+DCF!$C$58)/DCF!$C$60*100 -> 835.87664
A19: 0.18 | B19: =(DCF!$C$47+(DCF!$N$12*$A19*(1-DCF!$N$27)+DCF!$N$31+DCF!$N$33)*(1+B$17)/(WACC!$B$22-B$17)/(1+WACC!$B$22)^DCF!$C$51+DCF!$C$58)/DCF!$C$60*100 -> 742.86089 | C19: =(DCF!$C$47+(DCF!$N$12*$A19*(1-DCF!$N$27)+DCF!$N$31+DCF!$N$33)*(1+C$17)/(WACC!$B$22-C$17)/(1+WACC!$B$22)^DCF!$C$51+DCF!$C$58)/DCF!$C$60*100 -> 766.92004 | D19: =(DCF!$C$47+(DCF!$N$12*$A19*(1-DCF!$N$27)+DCF!$N$31+DCF!$N$33)*(1+D$17)/(WACC!$B$22-D$17)/(1+WACC!$B$22)^DCF!$C$51+DCF!$C$58)/DCF!$C$60*100 -> 794.28641 | E19: =(DCF!$C$47+(DCF!$N$12*$A19*(1-DCF!$N$27)+DCF!$N$31+DCF!$N$33)*(1+E$17)/(WACC!$B$22-E$17)/(1+WACC!$B$22)^DCF!$C$51+DCF!$C$58)/DCF!$C$60*100 -> 825.69225 | F19: =(DCF!$C$47+(DCF!$N$12*$A19*(1-DCF!$N$27)+DCF!$N$31+DCF!$N$33)*(1+F$17)/(WACC!$B$22-F$17)/(1+WACC!$B$22)^DCF!$C$51+DCF!$C$58)/DCF!$C$60*100 -> 862.10323
A20: 0.19 | B20: =(DCF!$C$47+(DCF!$N$12*$A20*(1-DCF!$N$27)+DCF!$N$31+DCF!$N$33)*(1+B$17)/(WACC!$B$22-B$17)/(1+WACC!$B$22)^DCF!$C$51+DCF!$C$58)/DCF!$C$60*100 -> 762.36329 | C20: =(DCF!$C$47+(DCF!$N$12*$A20*(1-DCF!$N$27)+DCF!$N$31+DCF!$N$33)*(1+C$17)/(WACC!$B$22-C$17)/(1+WACC!$B$22)^DCF!$C$51+DCF!$C$58)/DCF!$C$60*100 -> 787.77916 | D20: =(DCF!$C$47+(DCF!$N$12*$A20*(1-DCF!$N$27)+DCF!$N$31+DCF!$N$33)*(1+D$17)/(WACC!$B$22-D$17)/(1+WACC!$B$22)^DCF!$C$51+DCF!$C$58)/DCF!$C$60*100 -> 816.68874 | E20: =(DCF!$C$47+(DCF!$N$12*$A20*(1-DCF!$N$27)+DCF!$N$31+DCF!$N$33)*(1+E$17)/(WACC!$B$22-E$17)/(1+WACC!$B$22)^DCF!$C$51+DCF!$C$58)/DCF!$C$60*100 -> 849.8656 | F20: =(DCF!$C$47+(DCF!$N$12*$A20*(1-DCF!$N$27)+DCF!$N$31+DCF!$N$33)*(1+F$17)/(WACC!$B$22-F$17)/(1+WACC!$B$22)^DCF!$C$51+DCF!$C$58)/DCF!$C$60*100 -> 888.32982
A21: 0.195 | B21: =(DCF!$C$47+(DCF!$N$12*$A21*(1-DCF!$N$27)+DCF!$N$31+DCF!$N$33)*(1+B$17)/(WACC!$B$22-B$17)/(1+WACC!$B$22)^DCF!$C$51+DCF!$C$58)/DCF!$C$60*100 -> 772.11449 | C21: =(DCF!$C$47+(DCF!$N$12*$A21*(1-DCF!$N$27)+DCF!$N$31+DCF!$N$33)*(1+C$17)/(WACC!$B$22-C$17)/(1+WACC!$B$22)^DCF!$C$51+DCF!$C$58)/DCF!$C$60*100 -> 798.20872 | D21: =(DCF!$C$47+(DCF!$N$12*$A21*(1-DCF!$N$27)+DCF!$N$31+DCF!$N$33)*(1+D$17)/(WACC!$B$22-D$17)/(1+WACC!$B$22)^DCF!$C$51+DCF!$C$58)/DCF!$C$60*100 -> 827.88991 | E21: =(DCF!$C$47+(DCF!$N$12*$A21*(1-DCF!$N$27)+DCF!$N$31+DCF!$N$33)*(1+E$17)/(WACC!$B$22-E$17)/(1+WACC!$B$22)^DCF!$C$51+DCF!$C$58)/DCF!$C$60*100 -> 861.95227 | F21: =(DCF!$C$47+(DCF!$N$12*$A21*(1-DCF!$N$27)+DCF!$N$31+DCF!$N$33)*(1+F$17)/(WACC!$B$22-F$17)/(1+WACC!$B$22)^DCF!$C$51+DCF!$C$58)/DCF!$C$60*100 -> 901.44312
A22: 0.2 | B22: =(DCF!$C$47+(DCF!$N$12*$A22*(1-DCF!$N$27)+DCF!$N$31+DCF!$N$33)*(1+B$17)/(WACC!$B$22-B$17)/(1+WACC!$B$22)^DCF!$C$51+DCF!$C$58)/DCF!$C$60*100 -> 781.86569 | C22: =(DCF!$C$47+(DCF!$N$12*$A22*(1-DCF!$N$27)+DCF!$N$31+DCF!$N$33)*(1+C$17)/(WACC!$B$22-C$17)/(1+WACC!$B$22)^DCF!$C$51+DCF!$C$58)/DCF!$C$60*100 -> 808.63828 | D22: =(DCF!$C$47+(DCF!$N$12*$A22*(1-DCF!$N$27)+DCF!$N$31+DCF!$N$33)*(1+D$17)/(WACC!$B$22-D$17)/(1+WACC!$B$22)^DCF!$C$51+DCF!$C$58)/DCF!$C$60*100 -> 839.09108 | E22: =(DCF!$C$47+(DCF!$N$12*$A22*(1-DCF!$N$27)+DCF!$N$31+DCF!$N$33)*(1+E$17)/(WACC!$B$22-E$17)/(1+WACC!$B$22)^DCF!$C$51+DCF!$C$58)/DCF!$C$60*100 -> 874.03894 | F22: =(DCF!$C$47+(DCF!$N$12*$A22*(1-DCF!$N$27)+DCF!$N$31+DCF!$N$33)*(1+F$17)/(WACC!$B$22-F$17)/(1+WACC!$B$22)^DCF!$C$51+DCF!$C$58)/DCF!$C$60*100 -> 914.55642
A23: 0.21 | B23: =(DCF!$C$47+(DCF!$N$12*$A23*(1-DCF!$N$27)+DCF!$N$31+DCF!$N$33)*(1+B$17)/(WACC!$B$22-B$17)/(1+WACC!$B$22)^DCF!$C$51+DCF!$C$58)/DCF!$C$60*100 -> 801.36809 | C23: =(DCF!$C$47+(DCF!$N$12*$A23*(1-DCF!$N$27)+DCF!$N$31+DCF!$N$33)*(1+C$17)/(WACC!$B$22-C$17)/(1+WACC!$B$22)^DCF!$C$51+DCF!$C$58)/DCF!$C$60*100 -> 829.4974 | D23: =(DCF!$C$47+(DCF!$N$12*$A23*(1-DCF!$N$27)+DCF!$N$31+DCF!$N$33)*(1+D$17)/(WACC!$B$22-D$17)/(1+WACC!$B$22)^DCF!$C$51+DCF!$C$58)/DCF!$C$60*100 -> 861.49342 | E23: =(DCF!$C$47+(DCF!$N$12*$A23*(1-DCF!$N$27)+DCF!$N$31+DCF!$N$33)*(1+E$17)/(WACC!$B$22-E$17)/(1+WACC!$B$22)^DCF!$C$51+DCF!$C$58)/DCF!$C$60*100 -> 898.21228 | F23: =(DCF!$C$47+(DCF!$N$12*$A23*(1-DCF!$N$27)+DCF!$N$31+DCF!$N$33)*(1+F$17)/(WACC!$B$22-F$17)/(1+WACC!$B$22)^DCF!$C$51+DCF!$C$58)/DCF!$C$60*100 -> 940.78301
A24: 0.22 | B24: =(DCF!$C$47+(DCF!$N$12*$A24*(1-DCF!$N$27)+DCF!$N$31+DCF!$N$33)*(1+B$17)/(WACC!$B$22-B$17)/(1+WACC!$B$22)^DCF!$C$51+DCF!$C$58)/DCF!$C$60*100 -> 820.87049 | C24: =(DCF!$C$47+(DCF!$N$12*$A24*(1-DCF!$N$27)+DCF!$N$31+DCF!$N$33)*(1+C$17)/(WACC!$B$22-C$17)/(1+WACC!$B$22)^DCF!$C$51+DCF!$C$58)/DCF!$C$60*100 -> 850.35652 | D24: =(DCF!$C$47+(DCF!$N$12*$A24*(1-DCF!$N$27)+DCF!$N$31+DCF!$N$33)*(1+D$17)/(WACC!$B$22-D$17)/(1+WACC!$B$22)^DCF!$C$51+DCF!$C$58)/DCF!$C$60*100 -> 883.89575 | E24: =(DCF!$C$47+(DCF!$N$12*$A24*(1-DCF!$N$27)+DCF!$N$31+DCF!$N$33)*(1+E$17)/(WACC!$B$22-E$17)/(1+WACC!$B$22)^DCF!$C$51+DCF!$C$58)/DCF!$C$60*100 -> 922.38563 | F24: =(DCF!$C$47+(DCF!$N$12*$A24*(1-DCF!$N$27)+DCF!$N$31+DCF!$N$33)*(1+F$17)/(WACC!$B$22-F$17)/(1+WACC!$B$22)^DCF!$C$51+DCF!$C$58)/DCF!$C$60*100 -> 967.00961
A26: Note: grid 2 flexes the terminal-year margin only; explicit-period cash flows are held at base case. Base-case 2035E group margin ≈ 19.5%.
